Traceback (most recent call last):
  File "/usr/lib/python3.10/runpy.py", line 196, in _run_module_as_main
    return _run_code(code, main_globals, None,
  File "/usr/lib/python3.10/runpy.py", line 86, in _run_code
    exec(code, run_globals)
  File "/home/joaquin_l_calvo/Trento/Data_Mining/Data-Mining-Project/src/training/evaluation.py", line 46, in <module>
    test_data_path = ALS_CONFIG.test_data_path
AttributeError: 'dict' object has no attribute 'test_data_path'
Traceback (most recent call last):
  File "/usr/lib/python3.10/runpy.py", line 196, in _run_module_as_main
    return _run_code(code, main_globals, None,
  File "/usr/lib/python3.10/runpy.py", line 86, in _run_code
    exec(code, run_globals)
  File "/home/joaquin_l_calvo/Trento/Data_Mining/Data-Mining-Project/src/training/evaluation.py", line 46, in <module>
    test_data_path = ALS_CONFIG.test_data_path
AttributeError: 'dict' object has no attribute 'test_data_path'
